{"uuid": "f57b3e5a-4aa4-498d-9703-ce6d8ad9cd5f", "children": ["42030808-ca26-47d5-a594-b53ffef5680b"], "befores": [{"name": "authorized_user", "status": "broken", "statusDetails": {"message": "playwright._impl._errors.TimeoutError: Page.goto: Timeout 30000ms exceeded.\nCall log:\n  - navigating to \"https://app.clickup.com/login\", waiting until \"load\"\n\n", "trace": "  File \"C:\\Users\\Sanchez\\Documents\\GitHub\\clickup_tests\\.venv\\Lib\\site-packages\\pluggy\\_callers.py\", line 167, in _multicall\n    teardown.throw(outcome._exception)\n  File \"C:\\Users\\Sanchez\\Documents\\GitHub\\clickup_tests\\.venv\\Lib\\site-packages\\_pytest\\setuponly.py\", line 36, in pytest_fixture_setup\n    return (yield)\n            ^^^^^\n  File \"C:\\Users\\Sanchez\\Documents\\GitHub\\clickup_tests\\.venv\\Lib\\site-packages\\pluggy\\_callers.py\", line 103, in _multicall\n    res = hook_impl.function(*args)\n          ^^^^^^^^^^^^^^^^^^^^^^^^^\n  File \"C:\\Users\\Sanchez\\Documents\\GitHub\\clickup_tests\\.venv\\Lib\\site-packages\\_pytest\\fixtures.py\", line 1140, in pytest_fixture_setup\n    result = call_fixture_func(fixturefunc, request, kwargs)\n             ^^^^^^^^^^^^^^^^^^^^^^^^^^^^^^^^^^^^^^^^^^^^^^^\n  File \"C:\\Users\\Sanchez\\Documents\\GitHub\\clickup_tests\\.venv\\Lib\\site-packages\\_pytest\\fixtures.py\", line 891, in call_fixture_func\n    fixture_result = next(generator)\n                     ^^^^^^^^^^^^^^^\n  File \"c:\\Users\\Sanchez\\Documents\\GitHub\\clickup_tests\\tests\\conftest.py\", line 86, in authorized_user\n    login_page.login(CLICKUP_EMAIL, CLICKUP_PASSWORD)\n  File \"C:\\Users\\Sanchez\\Documents\\GitHub\\clickup_tests\\pages\\login_page.py\", line 14, in login\n    self.navigate_to()\n  File \"C:\\Users\\Sanchez\\Documents\\GitHub\\clickup_tests\\pages\\base_page.py\", line 18, in navigate_to\n    self.page.goto(full_url)\n  File \"C:\\Users\\Sanchez\\Documents\\GitHub\\clickup_tests\\.venv\\Lib\\site-packages\\playwright\\sync_api\\_generated.py\", line 9020, in goto\n    self._sync(\n  File \"C:\\Users\\Sanchez\\Documents\\GitHub\\clickup_tests\\.venv\\Lib\\site-packages\\playwright\\_impl\\_sync_base.py\", line 115, in _sync\n    return task.result()\n           ^^^^^^^^^^^^^\n  File \"C:\\Users\\Sanchez\\Documents\\GitHub\\clickup_tests\\.venv\\Lib\\site-packages\\playwright\\_impl\\_page.py\", line 552, in goto\n    return await self._main_frame.goto(**locals_to_params(locals()))\n           ^^^^^^^^^^^^^^^^^^^^^^^^^^^^^^^^^^^^^^^^^^^^^^^^^^^^^^^^^\n  File \"C:\\Users\\Sanchez\\Documents\\GitHub\\clickup_tests\\.venv\\Lib\\site-packages\\playwright\\_impl\\_frame.py\", line 145, in goto\n    await self._channel.send(\"goto\", locals_to_params(locals()))\n  File \"C:\\Users\\Sanchez\\Documents\\GitHub\\clickup_tests\\.venv\\Lib\\site-packages\\playwright\\_impl\\_connection.py\", line 61, in send\n    return await self._connection.wrap_api_call(\n           ^^^^^^^^^^^^^^^^^^^^^^^^^^^^^^^^^^^^^\n  File \"C:\\Users\\Sanchez\\Documents\\GitHub\\clickup_tests\\.venv\\Lib\\site-packages\\playwright\\_impl\\_connection.py\", line 528, in wrap_api_call\n    raise rewrite_error(error, f\"{parsed_st['apiName']}: {error}\") from None\n"}, "steps": [{"name": "Запуск браузера и выполнение авторизации через UI", "status": "broken", "statusDetails": {"message": "playwright._impl._errors.TimeoutError: Page.goto: Timeout 30000ms exceeded.\nCall log:\n  - navigating to \"https://app.clickup.com/login\", waiting until \"load\"\n\n", "trace": "  File \"c:\\Users\\Sanchez\\Documents\\GitHub\\clickup_tests\\tests\\conftest.py\", line 86, in authorized_user\n    login_page.login(CLICKUP_EMAIL, CLICKUP_PASSWORD)\n  File \"C:\\Users\\Sanchez\\Documents\\GitHub\\clickup_tests\\pages\\login_page.py\", line 14, in login\n    self.navigate_to()\n  File \"C:\\Users\\Sanchez\\Documents\\GitHub\\clickup_tests\\pages\\base_page.py\", line 18, in navigate_to\n    self.page.goto(full_url)\n  File \"C:\\Users\\Sanchez\\Documents\\GitHub\\clickup_tests\\.venv\\Lib\\site-packages\\playwright\\sync_api\\_generated.py\", line 9020, in goto\n    self._sync(\n  File \"C:\\Users\\Sanchez\\Documents\\GitHub\\clickup_tests\\.venv\\Lib\\site-packages\\playwright\\_impl\\_sync_base.py\", line 115, in _sync\n    return task.result()\n           ^^^^^^^^^^^^^\n  File \"C:\\Users\\Sanchez\\Documents\\GitHub\\clickup_tests\\.venv\\Lib\\site-packages\\playwright\\_impl\\_page.py\", line 552, in goto\n    return await self._main_frame.goto(**locals_to_params(locals()))\n           ^^^^^^^^^^^^^^^^^^^^^^^^^^^^^^^^^^^^^^^^^^^^^^^^^^^^^^^^^\n  File \"C:\\Users\\Sanchez\\Documents\\GitHub\\clickup_tests\\.venv\\Lib\\site-packages\\playwright\\_impl\\_frame.py\", line 145, in goto\n    await self._channel.send(\"goto\", locals_to_params(locals()))\n  File \"C:\\Users\\Sanchez\\Documents\\GitHub\\clickup_tests\\.venv\\Lib\\site-packages\\playwright\\_impl\\_connection.py\", line 61, in send\n    return await self._connection.wrap_api_call(\n           ^^^^^^^^^^^^^^^^^^^^^^^^^^^^^^^^^^^^^\n  File \"C:\\Users\\Sanchez\\Documents\\GitHub\\clickup_tests\\.venv\\Lib\\site-packages\\playwright\\_impl\\_connection.py\", line 528, in wrap_api_call\n    raise rewrite_error(error, f\"{parsed_st['apiName']}: {error}\") from None\n"}, "steps": [{"name": "Вход в систему", "status": "broken", "statusDetails": {"message": "playwright._impl._errors.TimeoutError: Page.goto: Timeout 30000ms exceeded.\nCall log:\n  - navigating to \"https://app.clickup.com/login\", waiting until \"load\"\n\n", "trace": "  File \"c:\\Users\\Sanchez\\Documents\\GitHub\\clickup_tests\\tests\\conftest.py\", line 86, in authorized_user\n    login_page.login(CLICKUP_EMAIL, CLICKUP_PASSWORD)\n  File \"C:\\Users\\Sanchez\\Documents\\GitHub\\clickup_tests\\pages\\login_page.py\", line 14, in login\n    self.navigate_to()\n  File \"C:\\Users\\Sanchez\\Documents\\GitHub\\clickup_tests\\pages\\base_page.py\", line 18, in navigate_to\n    self.page.goto(full_url)\n  File \"C:\\Users\\Sanchez\\Documents\\GitHub\\clickup_tests\\.venv\\Lib\\site-packages\\playwright\\sync_api\\_generated.py\", line 9020, in goto\n    self._sync(\n  File \"C:\\Users\\Sanchez\\Documents\\GitHub\\clickup_tests\\.venv\\Lib\\site-packages\\playwright\\_impl\\_sync_base.py\", line 115, in _sync\n    return task.result()\n           ^^^^^^^^^^^^^\n  File \"C:\\Users\\Sanchez\\Documents\\GitHub\\clickup_tests\\.venv\\Lib\\site-packages\\playwright\\_impl\\_page.py\", line 552, in goto\n    return await self._main_frame.goto(**locals_to_params(locals()))\n           ^^^^^^^^^^^^^^^^^^^^^^^^^^^^^^^^^^^^^^^^^^^^^^^^^^^^^^^^^\n  File \"C:\\Users\\Sanchez\\Documents\\GitHub\\clickup_tests\\.venv\\Lib\\site-packages\\playwright\\_impl\\_frame.py\", line 145, in goto\n    await self._channel.send(\"goto\", locals_to_params(locals()))\n  File \"C:\\Users\\Sanchez\\Documents\\GitHub\\clickup_tests\\.venv\\Lib\\site-packages\\playwright\\_impl\\_connection.py\", line 61, in send\n    return await self._connection.wrap_api_call(\n           ^^^^^^^^^^^^^^^^^^^^^^^^^^^^^^^^^^^^^\n  File \"C:\\Users\\Sanchez\\Documents\\GitHub\\clickup_tests\\.venv\\Lib\\site-packages\\playwright\\_impl\\_connection.py\", line 528, in wrap_api_call\n    raise rewrite_error(error, f\"{parsed_st['apiName']}: {error}\") from None\n"}, "start": 1744800130252, "stop": 1744800160269}], "start": 1744800129690, "stop": 1744800160270}], "start": 1744800129690, "stop": 1744800160271}], "start": 1744800129690, "stop": 1744800160381}